<?xml version="1.0"?>
<robot name="slidertable">

  <material name="black">
    <color rgba="0.1 0.1 0.1 1"/>
  </material>
  <material name="darkgrey">
    <color rgba="0.2 0.2 0.2 1"/>
  </material>
  <material name="beige">
    <color rgba=".78 .78 .63 1"/>
  </material>
  <material name="white">
    <color rgba="1 1 1 1"/>
  </material>
  <material name="orange">
    <color rgba="1 0.58 0.28 1"/>
  </material>

  <material name="simred">
    <color rgba="1 0 0 0.5"/>
  </material>

  <link name="tabletop">
    <visual>
      <geometry>
        <box size="1.22 1.22 0.025"/>
      </geometry>
      <material name="black"/>
    </visual>
  </link>

  <link name="baseboard">
    <visual>
      <geometry>
        <box size="0.1778 0.4826 0.01905"/>
      </geometry>
      <material name="beige"/>
    </visual>
  </link>

  <link name="slider">
    <visual>
      <geometry>
        <box size="0.1524 0.762 0.01905"/>
      </geometry>
      <material name="beige"/>
    </visual>
  </link>

  <link name="simslider">
    <visual>
      <geometry>
        <box size="0.1524 0.762 0.01905"/>
      </geometry>
      <material name="simred"/>
    </visual>
  </link>

  <joint name="tabletop_to_baseboard" type="fixed">
    <parent link="tabletop"/>
    <child link="baseboard"/>
    <origin rpy="0 0 3.14" xyz="0 0 0.022"/>
  </joint>


  <joint name="baseboard_to_slider" type="prismatic">
    <axis xyz="0 1 0"/>
    <parent link="baseboard"/>
    <child link="slider"/>
	<origin rpy="0 0 0" xyz="0 0 0.028575"/>
    <limit effort="1000.0" lower="-0.3" upper="0.3" velocity="0.5"/>
  </joint>

  <joint name="baseboard_to_simslider" type="prismatic">
    <axis xyz="0 1 0"/>
    <parent link="baseboard"/>
    <child link="simslider"/>
	<origin rpy="0 0 0" xyz="0 0 0.028575"/>
    <limit effort="1000.0" lower="-0.3" upper="0.3" velocity="0.5"/>
  </joint>

  <link name="ball_knob_1">
    <visual>
      <geometry>
        <sphere radius="0.024"/>
      </geometry>

      <material name="darkgrey"/>
    </visual>
  </link>

  <joint name="slider_to_knob1" type="fixed">
    <parent link="slider"/>
    <child link="ball_knob_1"/>
    <origin rpy="3.14 0 1.57" xyz="0 -0.43 0.0381"/>
  </joint>


  <link name="ball_knob_2">
    <visual>
      <geometry>
        <sphere radius="0.024"/>
      </geometry>

      <material name="darkgrey"/>
    </visual>
  </link>

  <joint name="slider_to_knob2" type="fixed">
    <parent link="slider"/>
    <child link="ball_knob_2"/>
    <origin rpy="3.14 0 -1.57" xyz="0 0.43 0.0381"/>
  </joint>
</robot>
